<?xml version='1.0'?>
<robot name="slambot" xmlns:xacro="http://www.ros.org/wiki/xacro">

    <link name="robot_footprint"></link>

    <joint name="robot_footprint_joint" type="fixed">
        <origin xyz="0 0 0" rpy="0 0 0" />
        <parent link="robot_footprint" />
        <child link="chassis" />
    </joint>

    <!-- Chassis Link -->
    <link name='chassis'>
        <visual name='chassis_visual'>
            <origin xyz="0 0 0" rpy=" 0 0 0" />
            <geometry>
                <box size="0.4 .15 .056" />
            </geometry>
        </visual>
    </link>

    <!-- Left Wheel Link -->
    <link name="left_wheel">
        <visual name="visual">
            <origin xyz="0 0 0" rpy="0 1.5708 0" />
            <geometry>
                <cylinder radius="0.032" length="0.026" />
            </geometry>
        </visual>
    </link>

    <!-- Left Wheel Joint -->
    <joint type="continuous" name="left_wheel_joint">
        <origin xyz="0 0.092 0" rpy="0 0 0" />
        <child link="left_wheel" />
        <parent link="chassis" />
        <axis xyz="0 0 1" />
        <limit effort="1.1" velocity="9.5" />
    </joint>

    <!-- Right Wheel Link -->
    <link name="right_wheel">
        <visual name="visual">
            <origin xyz="0 0 0" rpy="0 1.5708 0" />
            <geometry>
                <cylinder radius="0.032" length="0.026" />
            </geometry>
        </visual>
    </link>

    <!-- Right Wheel Joint -->
    <joint type="continuous" name="right_wheel_hinge">
        <origin xyz="0 -0.092 0" rpy="0 0 0" />
        <child link="right_wheel" />
        <parent link="chassis" />
        <axis xyz="0 0 1" />
        <limit effort="1.1" velocity="9.5" />
    </joint>


    <!-- <link name="slamtec_mapper">
        <inertial>
            <mass value="0.1" />
            <origin xyz="0 0 0" rpy="0 0 0" />
            <inertia
                ixx="1e-6" ixy="0" ixz="0"
                iyy="1e-6" iyz="0"
                izz="1e-6"
            />
        </inertial>

        <collision name="collision">
            <origin xyz="0 0 0" rpy="0 0 0" />
            <geometry>
                <box size="0.1 0.1 0.1" />
            </geometry>
        </collision>

        <visual name="visual">
            <origin xyz="0 0 0" rpy="0 0 0" />
            <geometry>
                <mesh filename="package://slam_project/meshes/hokuyo.dae" />
            </geometry>
        </visual>
    </link>

    <joint type="fixed" name="hokuyo_joint">
        <origin xyz="0.15 0 0.1" rpy="0 0 0" />
        <child link="hokuyo" />
        <parent link="chassis" />
    </joint> -->

    <transmission name="left_wheel_trans">
        <type>transmission_interface/SimpleTransmission</type>
        <joint name="left_wheel_joint">
            <hardwareInterface>hardware_interface/VelocityJointInterface</hardwareInterface>
        </joint>
    </transmission>

    <transmission name="right_wheel_trans">
        <type>transmission_interface/SimpleTransmission</type>
        <joint name="right_wheel_hinge">
            <hardwareInterface>hardware_interface/VelocityJointInterface</hardwareInterface>
        </joint>
    </transmission>

</robot>